Traceback (most recent call last):
  File "/Users/ildarzalaliev/Desktop/mlops_rep/mlopsiu_team4/.venv/lib/python3.12/site-packages/psutil/_psosx.py", line 349, in wrapper
    return fun(self, *args, **kwargs)
           ^^^^^^^^^^^^^^^^^^^^^^^^^^
  File "/Users/ildarzalaliev/Desktop/mlops_rep/mlopsiu_team4/.venv/lib/python3.12/site-packages/psutil/_common.py", line 508, in wrapper
    raise raise_from(err, None)
          ^^^^^^^^^^^^^^^^^^^^^
  File "<string>", line 3, in raise_from
  File "/Users/ildarzalaliev/Desktop/mlops_rep/mlopsiu_team4/.venv/lib/python3.12/site-packages/psutil/_common.py", line 506, in wrapper
    return fun(self)
           ^^^^^^^^^
  File "/Users/ildarzalaliev/Desktop/mlops_rep/mlopsiu_team4/.venv/lib/python3.12/site-packages/psutil/_psosx.py", line 375, in _get_kinfo_proc
    ret = cext.proc_kinfo_oneshot(self.pid)
          ^^^^^^^^^^^^^^^^^^^^^^^^^^^^^^^^^
ProcessLookupError: [Errno 3] assume no such process (originated from sysctl(kinfo_proc), len == 0)

During handling of the above exception, another exception occurred:

Traceback (most recent call last):
  File "/Users/ildarzalaliev/Desktop/mlops_rep/mlopsiu_team4/.venv/lib/python3.12/site-packages/psutil/__init__.py", line 355, in _init
    self.create_time()
  File "/Users/ildarzalaliev/Desktop/mlops_rep/mlopsiu_team4/.venv/lib/python3.12/site-packages/psutil/__init__.py", line 757, in create_time
    self._create_time = self._proc.create_time()
                        ^^^^^^^^^^^^^^^^^^^^^^^^
  File "/Users/ildarzalaliev/Desktop/mlops_rep/mlopsiu_team4/.venv/lib/python3.12/site-packages/psutil/_psosx.py", line 349, in wrapper
    return fun(self, *args, **kwargs)
           ^^^^^^^^^^^^^^^^^^^^^^^^^^
  File "/Users/ildarzalaliev/Desktop/mlops_rep/mlopsiu_team4/.venv/lib/python3.12/site-packages/psutil/_psosx.py", line 477, in create_time
    return self._get_kinfo_proc()[kinfo_proc_map['ctime']]
           ^^^^^^^^^^^^^^^^^^^^^^
  File "/Users/ildarzalaliev/Desktop/mlops_rep/mlopsiu_team4/.venv/lib/python3.12/site-packages/psutil/_psosx.py", line 354, in wrapper
    raise NoSuchProcess(self.pid, self._name)
psutil.NoSuchProcess: process no longer exists (pid=40540)

During handling of the above exception, another exception occurred:

Traceback (most recent call last):
  File "/Users/ildarzalaliev/Desktop/mlops_rep/mlopsiu_team4/.venv/lib/python3.12/site-packages/airflow/cli/commands/daemon_utils.py", line 80, in run_command_with_daemon_option
    callback()
  File "/Users/ildarzalaliev/Desktop/mlops_rep/mlopsiu_team4/.venv/lib/python3.12/site-packages/airflow/cli/commands/webserver_command.py", line 488, in <lambda>
    callback=lambda: start_and_monitor_gunicorn(args),
                     ^^^^^^^^^^^^^^^^^^^^^^^^^^^^^^^^
  File "/Users/ildarzalaliev/Desktop/mlops_rep/mlopsiu_team4/.venv/lib/python3.12/site-packages/airflow/cli/commands/webserver_command.py", line 472, in start_and_monitor_gunicorn
    monitor_gunicorn(gunicorn_master_proc)
  File "/Users/ildarzalaliev/Desktop/mlops_rep/mlopsiu_team4/.venv/lib/python3.12/site-packages/airflow/cli/commands/webserver_command.py", line 457, in monitor_gunicorn
    ).start()
      ^^^^^^^
  File "/Users/ildarzalaliev/Desktop/mlops_rep/mlopsiu_team4/.venv/lib/python3.12/site-packages/airflow/cli/commands/webserver_command.py", line 218, in start
    self._check_workers()
  File "/Users/ildarzalaliev/Desktop/mlops_rep/mlopsiu_team4/.venv/lib/python3.12/site-packages/airflow/cli/commands/webserver_command.py", line 264, in _check_workers
    num_workers_running = self._get_num_workers_running()
                          ^^^^^^^^^^^^^^^^^^^^^^^^^^^^^^^
  File "/Users/ildarzalaliev/Desktop/mlops_rep/mlopsiu_team4/.venv/lib/python3.12/site-packages/airflow/cli/commands/webserver_command.py", line 151, in _get_num_workers_running
    workers = psutil.Process(self.gunicorn_master_proc.pid).children()
              ^^^^^^^^^^^^^^^^^^^^^^^^^^^^^^^^^^^^^^^^^^^^^
  File "/Users/ildarzalaliev/Desktop/mlops_rep/mlopsiu_team4/.venv/lib/python3.12/site-packages/psutil/__init__.py", line 319, in __init__
    self._init(pid)
  File "/Users/ildarzalaliev/Desktop/mlops_rep/mlopsiu_team4/.venv/lib/python3.12/site-packages/psutil/__init__.py", line 368, in _init
    raise NoSuchProcess(pid, msg=msg)
psutil.NoSuchProcess: process PID not found (pid=40540)

During handling of the above exception, another exception occurred:

Traceback (most recent call last):
  File "/Users/ildarzalaliev/Desktop/mlops_rep/mlopsiu_team4/.venv/bin/airflow", line 8, in <module>
    sys.exit(main())
             ^^^^^^
  File "/Users/ildarzalaliev/Desktop/mlops_rep/mlopsiu_team4/.venv/lib/python3.12/site-packages/airflow/__main__.py", line 58, in main
    args.func(args)
  File "/Users/ildarzalaliev/Desktop/mlops_rep/mlopsiu_team4/.venv/lib/python3.12/site-packages/airflow/cli/cli_config.py", line 49, in command
    return func(*args, **kwargs)
           ^^^^^^^^^^^^^^^^^^^^^
  File "/Users/ildarzalaliev/Desktop/mlops_rep/mlopsiu_team4/.venv/lib/python3.12/site-packages/airflow/utils/cli.py", line 114, in wrapper
    return f(*args, **kwargs)
           ^^^^^^^^^^^^^^^^^^
  File "/Users/ildarzalaliev/Desktop/mlops_rep/mlopsiu_team4/.venv/lib/python3.12/site-packages/airflow/utils/providers_configuration_loader.py", line 55, in wrapped_function
    return func(*args, **kwargs)
           ^^^^^^^^^^^^^^^^^^^^^
  File "/Users/ildarzalaliev/Desktop/mlops_rep/mlopsiu_team4/.venv/lib/python3.12/site-packages/airflow/cli/commands/webserver_command.py", line 485, in webserver
    run_command_with_daemon_option(
  File "/Users/ildarzalaliev/Desktop/mlops_rep/mlopsiu_team4/.venv/lib/python3.12/site-packages/airflow/cli/commands/daemon_utils.py", line 75, in run_command_with_daemon_option
    with ctx:
  File "/Users/ildarzalaliev/Desktop/mlops_rep/mlopsiu_team4/.venv/lib/python3.12/site-packages/daemon/daemon.py", line 397, in __exit__
    self.close()
  File "/Users/ildarzalaliev/Desktop/mlops_rep/mlopsiu_team4/.venv/lib/python3.12/site-packages/daemon/daemon.py", line 391, in close
    self.pidfile.__exit__(None, None, None)
  File "/Users/ildarzalaliev/Desktop/mlops_rep/mlopsiu_team4/.venv/lib/python3.12/site-packages/lockfile/__init__.py", line 204, in __exit__
    self.release()
  File "/Users/ildarzalaliev/Desktop/mlops_rep/mlopsiu_team4/.venv/lib/python3.12/site-packages/lockfile/pidlockfile.py", line 103, in release
    raise NotLocked("%s is not locked" % self.path)
lockfile.NotLocked: /Users/ildarzalaliev/Desktop/mlops_rep/mlopsiu_team4/services/airflow/airflow-webserver-monitor.pid is not locked
Exception ignored in atexit callback: <bound method DaemonContext.close of <daemon.daemon.DaemonContext object at 0x129c12630>>
Traceback (most recent call last):
  File "/Users/ildarzalaliev/Desktop/mlops_rep/mlopsiu_team4/.venv/lib/python3.12/site-packages/daemon/daemon.py", line 391, in close
    self.pidfile.__exit__(None, None, None)
  File "/Users/ildarzalaliev/Desktop/mlops_rep/mlopsiu_team4/.venv/lib/python3.12/site-packages/lockfile/__init__.py", line 204, in __exit__
    self.release()
  File "/Users/ildarzalaliev/Desktop/mlops_rep/mlopsiu_team4/.venv/lib/python3.12/site-packages/lockfile/pidlockfile.py", line 103, in release
    raise NotLocked("%s is not locked" % self.path)
lockfile.NotLocked: /Users/ildarzalaliev/Desktop/mlops_rep/mlopsiu_team4/services/airflow/airflow-webserver-monitor.pid is not locked
